Traceback (most recent call last):
  File "c:\Users\vj900\Desktop\Proyectos programacion\mailsender\python-bulk-mail-master\mail.py", line 21, in <module>
    server.login(sender_email, password)
  File "C:\Users\vj900\AppData\Local\Programs\Python\Python39\lib\smtplib.py", line 745, in login
    raise last_exception
  File "C:\Users\vj900\AppData\Local\Programs\Python\Python39\lib\smtplib.py", line 734, in login
    (code, resp) = self.auth(
  File "C:\Users\vj900\AppData\Local\Programs\Python\Python39\lib\smtplib.py", line 657, in auth
    raise SMTPAuthenticationError(code, resp)
smtplib.SMTPAuthenticationError: (535, b'5.7.8 Error: authentication failed: UGFzc3dvcmQ6')
